Workbook

Sheet Resumo
A1: RESIDÊNCIA Q22 · L8 — PLANILHA DE CUSTOS E MATERIAIS
A2: Gerada automaticamente a partir dos dados do painel de obra · NÃO editar à mão
A3: Gerada em 27/07/2026 00:49 (BRT)
A5: INDICADOR | B5: VALOR | D5: OBSERVAÇÃO
A6: Área construída | B6: 183 | C6: m² | D6: térreo 75 + garagem 27,5 + superior 62 + extensão 18
A7: Estimativa — faixa baixa | B7: =SUM(Etapas!C3:C15) | D7: soma das 13 etapas
A8: Estimativa — faixa alta | B8: =SUM(Etapas!D3:D15) | D8: soma das 13 etapas
A9: Custo/m² — baixo | B9: =B7/B6 | D9: referência CUB-SP R8-N: R$ 2.129,86
A10: Custo/m² — alto | B10: =B8/B6 | D10: diferença = sistemas premium (bomba de calor, automação, resinados)
A11: Total cotado/contratado | B11: =SUM(Cotações!K2:K2) | D11: soma de tudo lançado no site
A12: ├ material | B12: =SUMIF(Cotações!C2:C2,"<>mão de obra",Cotações!K2:K2)
A13: └ mão de obra | B13: =SUMIF(Cotações!C2:C2,"mão de obra",Cotações!K2:K2) | D13: empreiteiros/equipes cotados por etapa
A14: Custo real informado | B14: =SUM(Etapas!I3:I15) | D14: digitado na aba Etapas do site
A15: Cotações registradas | B15: =COUNTA(Cotações!A2:A2) | D15: cada lançamento = 1 commit no repositório
A16: Avanço geral (ponderado por custo) | B16: =IFERROR(SUMPRODUCT(Etapas!H3:H15,Etapas!E3:E15)/SUM(Etapas!E3:E15),0) | D16: ponderado pela média da faixa de cada etapa
A17: Etapas concluídas | B17: =COUNTIF(Etapas!G3:G15,"concluída") | C17: de 13
A19: SISTEMA CONSTRUTIVO (revisão atual)
A20: Paredes estruturais | B20: Monolev ~320 m² líquidos — perímetro + estruturais do térreo (divisa da garagem, testada)
A21: Divisórias em Lightwall | B21: Lightwall 2P 90 mm ~100 m²: todo o pav. superior (conceito mezanino) + caixas do lavabo e do banheiro do térreo — nenhuma delas é estrutural
A22: Lajes | B22: Vigotas + EPS ~86 m² — SÓ pisos (superior, extensão, técnica). Não há laje de forro.
A23: Forro | B23: Madeira acompanhando o telhado ~45 m² (mezanino + vão duplo) · gesso+EPS nivelado ~47 m² (demais)
A24: Cobertura | B24: 3 treliças galvanizadas a fogo @3,25 m (banzos paralelos h=0,40, degrau triangulado) + terças Ue 100 · ~1,0 t
A25: Faixa NE (1,20) | B25: Da fachada ao fundo: portinha (0,80) · Luz 1 = jardim de inverno c/ parede verde e janelão 3,50 (4,10) · PAREDE CEGA · Luz 2 = varal (4,10) · lavanderia + área técnica acima (4,00, único trecho coberto até a divisa)
A26: Fundação | B26: Radier ~103 m²
A27: Exaustão da ilha | B27: Plenum no forro c/ 2 frestas lineares de 30 mm + luz integrada · 1.100 m³/h · duto Ø250 · motor inline REMOTO na área técnica (32-38 dB(A) na cozinha) · liga sozinho pelo consumo do circuito do Invisacook
A28: Área técnica | B28: ABERTA (sem porta, só portão-gradil) — garante ar para a bomba de calor · acesso por escada marinheiro na parede da Luz 2 · equipamentos em IP65
A29: COMO USAR | B29: Calhas retangulares 150×100 nas 2 bordas longas (i=0,5% p/ o fundo) + 2 condutores Ø100 · I=172 mm/h · 108 m² de captação · rufos em chapa galv. #24
A30: Esta planilha é um EXPORT do painel de obra e é regerada a cada cotação lançada no site. Edições feitas aqui serão perdidas na próxima geração — lance tudo pelo site (pvizioli.github.io/projeto_casa_pedro) para que vire commit e volte para cá.
A33: Térreo — faixa SO | B33: Lavabo 1,50 × 1,50 no canto da garagem c/ o corredor (janela p/ o corredor) · despensa (1,50 × 1,10) + bancada + banheiro completo (1,50 × 2,50, sem box) no fundo, porta ÚNICA p/ a área gourmet

Sheet Etapas
A1: ETAPAS DA OBRA — 13 FASES
A2: # | B2: Etapa | C2: Estim. baixa | D2: Estim. alta | E2: Média | F2: % do total | G2: Status | H2: Avanço | I2: Custo real | J2: Cotado material | K2: Cotado mão de obra | L2: Cotado total | M2: Δ vs. alta | N2: Observação
A3: 1 | B3: Projetos, sondagem e aprovações | C3: 34000 | D3: 78000 | E3: =(C3+D3)/2 | F3: =IFERROR(E3/$E$16,0) | G3: não iniciada | H3: 0 | I3: 0 | J3: =SUMIFS(Cotações!$K$2:$K$2,Cotações!$G$2:$G$2,$A3,Cotações!$C$2:$C$2,"<>mão de obra") | K3: =SUMIFS(Cotações!$K$2:$K$2,Cotações!$G$2:$G$2,$A3,Cotações!$C$2:$C$2,"mão de obra") | L3: =J3+K3 | M3: =IF(L3=0,"",D3-L3) | N3: arquitetônico (legal+executivo) 12–27k · estrutural 5–12k · complementares 5–10k · AVAC 1,5–3k · SPT 2–4k · ART/RRT 1–2k · aprovações 1,5–4k · RT de execução 8–25k (10 meses) — detalhado na categoria Projetos e Serviços Técnicos
A4: 2 | B4: Fundação (radier 103 m²) + muro de divisa 210 m² | C4: 50500 | D4: 78500 | E4: =(C4+D4)/2 | F4: =IFERROR(E4/$E$16,0) | G4: não iniciada | H4: 0 | I4: 0 | J4: =SUMIFS(Cotações!$K$2:$K$2,Cotações!$G$2:$G$2,$A4,Cotações!$C$2:$C$2,"<>mão de obra") | K4: =SUMIFS(Cotações!$K$2:$K$2,Cotações!$G$2:$G$2,$A4,Cotações!$C$2:$C$2,"mão de obra") | L4: =J4+K4 | M4: =IF(L4=0,"",D4-L4) | N4: radier inclui eletroduto da ilha e hidráulica embutida · muro pré-moldado (placa) 210 m² (2×30,00 laterais + 10,00 fundo, h=3,00) — sistema mais econômico do mercado, ~30% mais barato que alvenaria convencional
A5: 3 | B5: Estrutura metálica | C5: 28000 | D5: 42000 | E5: =(C5+D5)/2 | F5: =IFERROR(E5/$E$16,0) | G5: não iniciada | H5: 0 | I5: 0 | J5: =SUMIFS(Cotações!$K$2:$K$2,Cotações!$G$2:$G$2,$A5,Cotações!$C$2:$C$2,"<>mão de obra") | K5: =SUMIFS(Cotações!$K$2:$K$2,Cotações!$G$2:$G$2,$A5,Cotações!$C$2:$C$2,"mão de obra") | L5: =J5+K5 | M5: =IF(L5=0,"",D5-L5) | N5: vigas (portão, testada 7,30, balanço sacada) + escada aberta
A6: 4 | B6: Paredes: Monolev (estrutural) + divisórias Lightwall | C6: 110000 | D6: 156000 | E6: =(C6+D6)/2 | F6: =IFERROR(E6/$E$16,0) | G6: não iniciada | H6: 0 | I6: 0 | J6: =SUMIFS(Cotações!$K$2:$K$2,Cotações!$G$2:$G$2,$A6,Cotações!$C$2:$C$2,"<>mão de obra") | K6: =SUMIFS(Cotações!$K$2:$K$2,Cotações!$G$2:$G$2,$A6,Cotações!$C$2:$C$2,"mão de obra") | L6: =J6+K6 | M6: =IF(L6=0,"",D6-L6) | N6: Monolev ~340 m² líq. (perímetro/estruturais + térreo) · divisórias internas do superior ~80 m² em Lightwall 2P 90 mm (conceito mezanino: só o perímetro segura o telhado) · juntas dissimilares Monolev↔Lightwall c/ tela + basecoat
A7: 5 | B7: Lajes de PISO (superior + sacada + técnica) | C7: 19000 | D7: 26000 | E7: =(C7+D7)/2 | F7: =IFERROR(E7/$E$16,0) | G7: não iniciada | H7: 0 | I7: 0 | J7: =SUMIFS(Cotações!$K$2:$K$2,Cotações!$G$2:$G$2,$A7,Cotações!$C$2:$C$2,"<>mão de obra") | K7: =SUMIFS(Cotações!$K$2:$K$2,Cotações!$G$2:$G$2,$A7,Cotações!$C$2:$C$2,"mão de obra") | L7: =J7+K7 | M7: =IF(L7=0,"",D7-L7) | N7: 86 m² vigotas + EPS + capa — apenas pisos estruturais; NÃO há laje de forro
A8: 6 | B8: Cobertura + lanternim | C8: 40000 | D8: 60000 | E8: =(C8+D8)/2 | F8: =IFERROR(E8/$E$16,0) | G8: não iniciada | H8: 0 | I8: 0 | J8: =SUMIFS(Cotações!$K$2:$K$2,Cotações!$G$2:$G$2,$A8,Cotações!$C$2:$C$2,"<>mão de obra") | K8: =SUMIFS(Cotações!$K$2:$K$2,Cotações!$G$2:$G$2,$A8,Cotações!$C$2:$C$2,"mão de obra") | L8: =J8+K8 | M8: =IF(L8=0,"",D8-L8) | N8: estrutura, telha sanduíche, vidro/básculas, rufos e calhas
A9: 7 | B9: Esquadrias e vidros | C9: 58000 | D9: 90000 | E9: =(C9+D9)/2 | F9: =IFERROR(E9/$E$16,0) | G9: não iniciada | H9: 0 | I9: 0 | J9: =SUMIFS(Cotações!$K$2:$K$2,Cotações!$G$2:$G$2,$A9,Cotações!$C$2:$C$2,"<>mão de obra") | K9: =SUMIFS(Cotações!$K$2:$K$2,Cotações!$G$2:$G$2,$A9,Cotações!$C$2:$C$2,"mão de obra") | L9: =J9+K9 | M9: =IF(L9=0,"",D9-L9) | N9: inclui janelão espelhado, porta balcão 3,5 m e da suíte 7 m
A10: 8 | B10: Hidráulica + água quente + prep. PV | C10: 33000 | D10: 52000 | E10: =(C10+D10)/2 | F10: =IFERROR(E10/$E$16,0) | G10: não iniciada | H10: 0 | I10: 0 | J10: =SUMIFS(Cotações!$K$2:$K$2,Cotações!$G$2:$G$2,$A10,Cotações!$C$2:$C$2,"<>mão de obra") | K10: =SUMIFS(Cotações!$K$2:$K$2,Cotações!$G$2:$G$2,$A10,Cotações!$C$2:$C$2,"mão de obra") | L10: =J10+K10 | M10: =IF(L10=0,"",D10-L10) | N10: bomba de calor, boiler 400 L, pressurização, PEX/manifold
A11: 9 | B11: Elétrica + automação + rede | C11: 45000 | D11: 70000 | E11: =(C11+D11)/2 | F11: =IFERROR(E11/$E$16,0) | G11: não iniciada | H11: 0 | I11: 0 | J11: =SUMIFS(Cotações!$K$2:$K$2,Cotações!$G$2:$G$2,$A11,Cotações!$C$2:$C$2,"<>mão de obra") | K11: =SUMIFS(Cotações!$K$2:$K$2,Cotações!$G$2:$G$2,$A11,Cotações!$C$2:$C$2,"mão de obra") | L11: =J11+K11 | M11: =IF(L11=0,"",D11-L11) | N11: trifásico, Home Assistant, câmeras, 220 V nos cômodos
A12: 10 | B12: Climatização | C12: 18000 | D12: 28000 | E12: =(C12+D12)/2 | F12: =IFERROR(E12/$E$16,0) | G12: não iniciada | H12: 0 | I12: 0 | J12: =SUMIFS(Cotações!$K$2:$K$2,Cotações!$G$2:$G$2,$A12,Cotações!$C$2:$C$2,"<>mão de obra") | K12: =SUMIFS(Cotações!$K$2:$K$2,Cotações!$G$2:$G$2,$A12,Cotações!$C$2:$C$2,"mão de obra") | L12: =J12+K12 | M12: =IF(L12=0,"",D12-L12) | N12: multi-split tri + split sala + destratificador, R-32
A13: 11 | B13: Acabamentos resinados (sem porcelanato) | C13: 48000 | D13: 82000 | E13: =(C13+D13)/2 | F13: =IFERROR(E13/$E$16,0) | G13: não iniciada | H13: 0 | I13: 0 | J13: =SUMIFS(Cotações!$K$2:$K$2,Cotações!$G$2:$G$2,$A13,Cotações!$C$2:$C$2,"<>mão de obra") | K13: =SUMIFS(Cotações!$K$2:$K$2,Cotações!$G$2:$G$2,$A13,Cotações!$C$2:$C$2,"mão de obra") | L13: =J13+K13 | M13: =IF(L13=0,"",D13-L13) | N13: resinados + carpete de pedra + microcimento · forro gesso+EPS ~47 m² (quartos/copa/banheiros/corredor) · forro de MADEIRA ~45 m² acompanhando o telhado (mezanino + vão duplo)
A14: 12 | B14: Gourmet (Invisacook, bancada, churrasqueira) | C14: 20000 | D14: 33000 | E14: =(C14+D14)/2 | F14: =IFERROR(E14/$E$16,0) | G14: não iniciada | H14: 0 | I14: 0 | J14: =SUMIFS(Cotações!$K$2:$K$2,Cotações!$G$2:$G$2,$A14,Cotações!$C$2:$C$2,"<>mão de obra") | K14: =SUMIFS(Cotações!$K$2:$K$2,Cotações!$G$2:$G$2,$A14,Cotações!$C$2:$C$2,"mão de obra") | L14: =J14+K14 | M14: =IF(L14=0,"",D14-L14) | N14: porcelanato sinterizado, cooktop gás externo
A15: 13 | B15: Canteiro, limpeza e imprevistos (~8%) | C15: 30000 | D15: 50000 | E15: =(C15+D15)/2 | F15: =IFERROR(E15/$E$16,0) | G15: não iniciada | H15: 0 | I15: 0 | J15: =SUMIFS(Cotações!$K$2:$K$2,Cotações!$G$2:$G$2,$A15,Cotações!$C$2:$C$2,"<>mão de obra") | K15: =SUMIFS(Cotações!$K$2:$K$2,Cotações!$G$2:$G$2,$A15,Cotações!$C$2:$C$2,"mão de obra") | L15: =J15+K15 | M15: =IF(L15=0,"",D15-L15) | N15: reserva técnica
B16: TOTAL | C16: =SUM(C3:C15) | D16: =SUM(D3:D15) | E16: =SUM(E3:E15) | F16: 100% | I16: =SUM(I3:I15) | J16: =SUM(J3:J15) | K16: =SUM(K3:K15) | L16: =SUM(L3:L15)

Sheet Itens
A1: CATÁLOGO DE ITENS COTÁVEIS
A2: Base do formulário de cotação do site. Quantidades = memória de cálculo do projeto.
A3: ID | B3: Categoria | C3: Tipo | D3: Etapa | E3: Item | F3: Especificação | G3: Un | H3: Qtde | I3: Nº cotações | J3: Melhor preço unit. | K3: Melhor fornecedor | L3: Melhor total | M3: Observação
A4: IT001 | B4: Geral / Estrutura | C4: material | D4: 4 | E4: Painéis EPS (Monolev) — parede líquida ESTRUTURAL (perímetro + estruturais do térreo) | G4: m² | H4: 320 | I4: =COUNTIFS(Cotações!$E$2:$E$2,$A4) | J4: =IF(I4=0,"—",_xlfn.MINIFS(Cotações!$J$2:$J$2,Cotações!$E$2:$E$2,$A4)) | K4: =IF(I4=0,"—",IFERROR(INDEX(Cotações!$H$2:$H$2,MATCH(1,INDEX((Cotações!$E$2:$E$2=$A4)*(Cotações!$J$2:$J$2=J4),0),0)),"")) | L4: =IF(I4=0,"—",IFERROR(J4*H4,"")) | M4: divisórias não estruturais (lavabo e banheiro do térreo + todo o superior) migradas p/ Lightwall
A5: IT002 | B5: Geral / Estrutura | C5: material | D5: 4 | E5: Argamassa projetada estrutural (2 faces) | G5: m² | H5: 640 | I5: =COUNTIFS(Cotações!$E$2:$E$2,$A5) | J5: =IF(I5=0,"—",_xlfn.MINIFS(Cotações!$J$2:$J$2,Cotações!$E$2:$E$2,$A5)) | K5: =IF(I5=0,"—",IFERROR(INDEX(Cotações!$H$2:$H$2,MATCH(1,INDEX((Cotações!$E$2:$E$2=$A5)*(Cotações!$J$2:$J$2=J5),0),0)),"")) | L5: =IF(I5=0,"—",IFERROR(J5*H5,"")) | M5: 2 faces × 320 m²
A6: IT003 | B6: Geral / Estrutura | C6: material | D6: 4 | E6: Telas de reforço e acessórios de canto — verba complementar | F6: telas de vão (diagonais sobre cantos de janela/porta), reforços de ancoragem e arremates não cobertos pela cantoneira | G6: vb | H6: 1 | I6: =COUNTIFS(Cotações!$E$2:$E$2,$A6) | J6: =IF(I6=0,"—",_xlfn.MINIFS(Cotações!$J$2:$J$2,Cotações!$E$2:$E$2,$A6)) | K6: =IF(I6=0,"—",IFERROR(INDEX(Cotações!$H$2:$H$2,MATCH(1,INDEX((Cotações!$E$2:$E$2=$A6)*(Cotações!$J$2:$J$2=J6),0),0)),"")) | L6: =IF(I6=0,"—",IFERROR(J6*H6,"")) | M6: cotar no pacote do painel · a cantoneira de canto está no item próprio (ver Cantoneira PVC c/ tela)
A7: IT004 | B7: Geral / Estrutura | C7: material | D7: 5 | E7: Laje vigotas + EPS — PISO do superior + técnica (estrutural) | G7: m² | H7: 70 | I7: =COUNTIFS(Cotações!$E$2:$E$2,$A7) | J7: =IF(I7=0,"—",_xlfn.MINIFS(Cotações!$J$2:$J$2,Cotações!$E$2:$E$2,$A7)) | K7: =IF(I7=0,"—",IFERROR(INDEX(Cotações!$H$2:$H$2,MATCH(1,INDEX((Cotações!$E$2:$E$2=$A7)*(Cotações!$J$2:$J$2=J7),0),0)),"")) | L7: =IF(I7=0,"—",IFERROR(J7*H7,"")) | M7: inclui capa de concreto · é o piso, não forro
A8: IT005 | B8: Geral / Estrutura | C8: material | D8: 2 | E8: Radier (fundação) | G8: m² | H8: 103 | I8: =COUNTIFS(Cotações!$E$2:$E$2,$A8) | J8: =IF(I8=0,"—",_xlfn.MINIFS(Cotações!$J$2:$J$2,Cotações!$E$2:$E$2,$A8)) | K8: =IF(I8=0,"—",IFERROR(INDEX(Cotações!$H$2:$H$2,MATCH(1,INDEX((Cotações!$E$2:$E$2=$A8)*(Cotações!$J$2:$J$2=J8),0),0)),"")) | L8: =IF(I8=0,"—",IFERROR(J8*H8,"")) | M8: casa 95 + extensão garagem 8
A9: IT006 | B9: Geral / Estrutura | C9: material | D9: 3 | E9: Vigas metálicas: testada da laje (7,30 livre, SEM pilar) + balanço da sacada 2,50 | G9: vb | H9: 1 | I9: =COUNTIFS(Cotações!$E$2:$E$2,$A9) | J9: =IF(I9=0,"—",_xlfn.MINIFS(Cotações!$J$2:$J$2,Cotações!$E$2:$E$2,$A9)) | K9: =IF(I9=0,"—",IFERROR(INDEX(Cotações!$H$2:$H$2,MATCH(1,INDEX((Cotações!$E$2:$E$2=$A9)*(Cotações!$J$2:$J$2=J9),0),0)),"")) | L9: =IF(I9=0,"—",IFERROR(J9*H9,"")) | M9: perfis I + engaste sob a suíte — projeto estrutural
A10: IT007 | B10: Geral / Estrutura | C10: material | D10: 6 | E10: Estrutura metálica da cobertura — 3 treliças galvanizadas a fogo + terças/contrav. Z275 | F10: 3 treliças banzos paralelos h=0,40 @3,25 (vão 7,30, degrau triangulado no lanternim): banzos tubo 50×50×2,00 · diagonais 30×30×2,00 · ~72 kg/un · terças Ue100×50×17×2,00 4 linhas @1,33/0,98 · contrav. Ø12 + esticador · vigotas Ue150 @1,25 sobre serviço · ~0,95-1,15 t | G10: m² | H10: 95 | I10: =COUNTIFS(Cotações!$E$2:$E$2,$A10) | J10: =IF(I10=0,"—",_xlfn.MINIFS(Cotações!$J$2:$J$2,Cotações!$E$2:$E$2,$A10)) | K10: =IF(I10=0,"—",IFERROR(INDEX(Cotações!$H$2:$H$2,MATCH(1,INDEX((Cotações!$E$2:$E$2=$A10)*(Cotações!$J$2:$J$2=J10),0),0)),"")) | L10: =IF(I10=0,"—",IFERROR(J10*H10,"")) | M10: treliças soldadas em fábrica e galvanizadas a fogo INTEIRAS, parafusadas em obra (tubos c/ furo de dreno) · oitões NO/SE apoiam direto na parede · plenum de 0,40 entre banzos p/ ventilador, luminárias e linhas do split · ver F-07/F-08/F-09
A11: IT008 | B11: Geral / Estrutura | C11: material | D11: 6 | E11: Telha sanduíche EPS | G11: m² | H11: 100 | I11: =COUNTIFS(Cotações!$E$2:$E$2,$A11) | J11: =IF(I11=0,"—",_xlfn.MINIFS(Cotações!$J$2:$J$2,Cotações!$E$2:$E$2,$A11)) | K11: =IF(I11=0,"—",IFERROR(INDEX(Cotações!$H$2:$H$2,MATCH(1,INDEX((Cotações!$E$2:$E$2=$A11)*(Cotações!$J$2:$J$2=J11),0),0)),"")) | L11: =IF(I11=0,"—",IFERROR(J11*H11,"")) | M11: não cobre a faixa de luz (8,20 × 1,20 descoberta) · cobre serviço/técnica (4,00 × 1,20)
A12: IT009 | B12: Geral / Estrutura | C12: material | D12: 6 | E12: Lanternim — vidro laminado/policarbonato + básculas | G12: m² | H12: 12 | I12: =COUNTIFS(Cotações!$E$2:$E$2,$A12) | J12: =IF(I12=0,"—",_xlfn.MINIFS(Cotações!$J$2:$J$2,Cotações!$E$2:$E$2,$A12)) | K12: =IF(I12=0,"—",IFERROR(INDEX(Cotações!$H$2:$H$2,MATCH(1,INDEX((Cotações!$E$2:$E$2=$A12)*(Cotações!$J$2:$J$2=J12),0),0)),"")) | L12: =IF(I12=0,"—",IFERROR(J12*H12,"")) | M12: 13 m × 0,90
A13: IT010 | B13: Geral / Estrutura | C13: material | D13: 6 | E13: Rufos e arremates — oitões, chaminé e lanternim | F13: chapa galvanizada #24 (0,65 mm) ou alumínio · dobra ≥150 mm na parede e ≥200 mm sobre a telha, com pingadeira | G13: vb | H13: 1 | I13: =COUNTIFS(Cotações!$E$2:$E$2,$A13) | J13: =IF(I13=0,"—",_xlfn.MINIFS(Cotações!$J$2:$J$2,Cotações!$E$2:$E$2,$A13)) | K13: =IF(I13=0,"—",IFERROR(INDEX(Cotações!$H$2:$H$2,MATCH(1,INDEX((Cotações!$E$2:$E$2=$A13)*(Cotações!$J$2:$J$2=J13),0),0)),"")) | L13: =IF(I13=0,"—",IFERROR(J13*H13,"")) | M13: ponto crítico de estanqueidade · lanternim tem rufo de topo E de base (ver F-09) · calhas em item próprio
A14: IT011 | B14: Geral / Estrutura | C14: material | D14: 3 | E14: Guarda-corpos (mezanino, corredor, escada) | G14: m | H14: 14 | I14: =COUNTIFS(Cotações!$E$2:$E$2,$A14) | J14: =IF(I14=0,"—",_xlfn.MINIFS(Cotações!$J$2:$J$2,Cotações!$E$2:$E$2,$A14)) | K14: =IF(I14=0,"—",IFERROR(INDEX(Cotações!$H$2:$H$2,MATCH(1,INDEX((Cotações!$E$2:$E$2=$A14)*(Cotações!$J$2:$J$2=J14),0),0)),"")) | L14: =IF(I14=0,"—",IFERROR(J14*H14,"")) | M14: metálico/vidro — definir
A15: IT012 | B15: Geral / Estrutura | C15: material | D15: 3 | E15: Escada metálica aberta (fachada norte) | G15: vb | H15: 1 | I15: =COUNTIFS(Cotações!$E$2:$E$2,$A15) | J15: =IF(I15=0,"—",_xlfn.MINIFS(Cotações!$J$2:$J$2,Cotações!$E$2:$E$2,$A15)) | K15: =IF(I15=0,"—",IFERROR(INDEX(Cotações!$H$2:$H$2,MATCH(1,INDEX((Cotações!$E$2:$E$2=$A15)*(Cotações!$J$2:$J$2=J15),0),0)),"")) | L15: =IF(I15=0,"—",IFERROR(J15*H15,"")) | M15: estrutura + degraus
A16: IT013 | B16: Geral / Estrutura | C16: material | D16: 7 | E16: Esquadrias (janelas, porta balcão, portas) | G16: vb | H16: 1 | I16: =COUNTIFS(Cotações!$E$2:$E$2,$A16) | J16: =IF(I16=0,"—",_xlfn.MINIFS(Cotações!$J$2:$J$2,Cotações!$E$2:$E$2,$A16)) | K16: =IF(I16=0,"—",IFERROR(INDEX(Cotações!$H$2:$H$2,MATCH(1,INDEX((Cotações!$E$2:$E$2=$A16)*(Cotações!$J$2:$J$2=J16),0),0)),"")) | L16: =IF(I16=0,"—",IFERROR(J16*H16,"")) | M16: detalhar por vão
A17: IT014 | B17: Geral / Estrutura | C17: material | D17: 9 | E17: Elétrica + automação — ver aba Elétrica | G17: vb | H17: 1 | I17: =COUNTIFS(Cotações!$E$2:$E$2,$A17) | J17: =IF(I17=0,"—",_xlfn.MINIFS(Cotações!$J$2:$J$2,Cotações!$E$2:$E$2,$A17)) | K17: =IF(I17=0,"—",IFERROR(INDEX(Cotações!$H$2:$H$2,MATCH(1,INDEX((Cotações!$E$2:$E$2=$A17)*(Cotações!$J$2:$J$2=J17),0),0)),"")) | L17: =IF(I17=0,"—",IFERROR(J17*H17,"")) | M17: quantitativo detalhado na aba própria
A18: IT015 | B18: Geral / Estrutura | C18: material | D18: 11 | E18: Impermeabilizações (banheiros, laje técnica) | G18: vb | H18: 1 | I18: =COUNTIFS(Cotações!$E$2:$E$2,$A18) | J18: =IF(I18=0,"—",_xlfn.MINIFS(Cotações!$J$2:$J$2,Cotações!$E$2:$E$2,$A18)) | K18: =IF(I18=0,"—",IFERROR(INDEX(Cotações!$H$2:$H$2,MATCH(1,INDEX((Cotações!$E$2:$E$2=$A18)*(Cotações!$J$2:$J$2=J18),0),0)),"")) | L18: =IF(I18=0,"—",IFERROR(J18*H18,"")) | M18: CRÍTICO: banheiros sem box drenam pela camada de pedra — impermeabilizar TODO o piso c/ caimento ao ralo oculto
A19: IT016 | B19: Geral / Estrutura | C19: material | D19: 8 | E19: Hidráulica completa + preparação PV | G19: vb | H19: 1 | I19: =COUNTIFS(Cotações!$E$2:$E$2,$A19) | J19: =IF(I19=0,"—",_xlfn.MINIFS(Cotações!$J$2:$J$2,Cotações!$E$2:$E$2,$A19)) | K19: =IF(I19=0,"—",IFERROR(INDEX(Cotações!$H$2:$H$2,MATCH(1,INDEX((Cotações!$E$2:$E$2=$A19)*(Cotações!$J$2:$J$2=J19),0),0)),"")) | L19: =IF(I19=0,"—",IFERROR(J19*H19,"")) | M19: ver aba Hidráulica
A20: IT017 | B20: Geral / Estrutura | C20: serviço | D20: 1 | E20: Sondagem SPT (2–3 furos) | F20: insumo do projeto de fundação (radier) | G20: vb | H20: 1 | I20: =COUNTIFS(Cotações!$E$2:$E$2,$A20) | J20: =IF(I20=0,"—",_xlfn.MINIFS(Cotações!$J$2:$J$2,Cotações!$E$2:$E$2,$A20)) | K20: =IF(I20=0,"—",IFERROR(INDEX(Cotações!$H$2:$H$2,MATCH(1,INDEX((Cotações!$E$2:$E$2=$A20)*(Cotações!$J$2:$J$2=J20),0),0)),"")) | L20: =IF(I20=0,"—",IFERROR(J20*H20,"")) | M20: fazer ANTES do projeto de fundação
A21: IT018 | B21: Geral / Estrutura | C21: material | D21: 10 | E21: Climatização — ver aba Climatização | G21: vb | H21: 1 | I21: =COUNTIFS(Cotações!$E$2:$E$2,$A21) | J21: =IF(I21=0,"—",_xlfn.MINIFS(Cotações!$J$2:$J$2,Cotações!$E$2:$E$2,$A21)) | K21: =IF(I21=0,"—",IFERROR(INDEX(Cotações!$H$2:$H$2,MATCH(1,INDEX((Cotações!$E$2:$E$2=$A21)*(Cotações!$J$2:$J$2=J21),0),0)),"")) | L21: =IF(I21=0,"—",IFERROR(J21*H21,"")) | M21: infra elétrica dos 5 pontos já na aba Elétrica
A22: IT019 | B22: Geral / Estrutura | C22: material | D22: 5 | E22: Laje da sacada/varanda (vigotas + EPS + capa) | G22: m² | H22: 18 | I22: =COUNTIFS(Cotações!$E$2:$E$2,$A22) | J22: =IF(I22=0,"—",_xlfn.MINIFS(Cotações!$J$2:$J$2,Cotações!$E$2:$E$2,$A22)) | K22: =IF(I22=0,"—",IFERROR(INDEX(Cotações!$H$2:$H$2,MATCH(1,INDEX((Cotações!$E$2:$E$2=$A22)*(Cotações!$J$2:$J$2=J22),0),0)),"")) | L22: =IF(I22=0,"—",IFERROR(J22*H22,"")) | M22: sobre vigas metálicas em balanço
A23: IT020 | B23: Geral / Estrutura | C23: material | D23: 11 | E23: Impermeabilização do piso da extensão (sobre varanda aberta) | G23: m² | H23: 18 | I23: =COUNTIFS(Cotações!$E$2:$E$2,$A23) | J23: =IF(I23=0,"—",_xlfn.MINIFS(Cotações!$J$2:$J$2,Cotações!$E$2:$E$2,$A23)) | K23: =IF(I23=0,"—",IFERROR(INDEX(Cotações!$H$2:$H$2,MATCH(1,INDEX((Cotações!$E$2:$E$2=$A23)*(Cotações!$J$2:$J$2=J23),0),0)),"")) | L23: =IF(I23=0,"—",IFERROR(J23*H23,"")) | M23: varanda gourmet abaixo
A24: IT021 | B24: Geral / Estrutura | C24: material | D24: 7 | E24: Mureta + envidraçamento da extensão da suíte (vidro até o forro) | G24: m² | H24: 21 | I24: =COUNTIFS(Cotações!$E$2:$E$2,$A24) | J24: =IF(I24=0,"—",_xlfn.MINIFS(Cotações!$J$2:$J$2,Cotações!$E$2:$E$2,$A24)) | K24: =IF(I24=0,"—",IFERROR(INDEX(Cotações!$H$2:$H$2,MATCH(1,INDEX((Cotações!$E$2:$E$2=$A24)*(Cotações!$J$2:$J$2=J24),0),0)),"")) | L24: =IF(I24=0,"—",IFERROR(J24*H24,"")) | M24: perímetro 12,3 m × ~1,7 m de vidro sobre mureta
A25: IT022 | B25: Geral / Estrutura | C25: material | D25: 11 | E25: Forro da extensão da suíte (esconde o V do telhado) | G25: m² | H25: 18 | I25: =COUNTIFS(Cotações!$E$2:$E$2,$A25) | J25: =IF(I25=0,"—",_xlfn.MINIFS(Cotações!$J$2:$J$2,Cotações!$E$2:$E$2,$A25)) | K25: =IF(I25=0,"—",IFERROR(INDEX(Cotações!$H$2:$H$2,MATCH(1,INDEX((Cotações!$E$2:$E$2=$A25)*(Cotações!$J$2:$J$2=J25),0),0)),"")) | L25: =IF(I25=0,"—",IFERROR(J25*H25,"")) | M25: gesso/PVC sobre a extensão · suíte integrada, sem porta
A26: IT023 | B26: Geral / Estrutura | C26: material | D26: 12 | E26: Churrasqueira + chaminé acima da cobertura | G26: vb | H26: 1 | I26: =COUNTIFS(Cotações!$E$2:$E$2,$A26) | J26: =IF(I26=0,"—",_xlfn.MINIFS(Cotações!$J$2:$J$2,Cotações!$E$2:$E$2,$A26)) | K26: =IF(I26=0,"—",IFERROR(INDEX(Cotações!$H$2:$H$2,MATCH(1,INDEX((Cotações!$E$2:$E$2=$A26)*(Cotações!$J$2:$J$2=J26),0),0)),"")) | L26: =IF(I26=0,"—",IFERROR(J26*H26,"")) | M26: canto leste da varanda
A27: IT024 | B27: Geral / Estrutura | C27: material | D27: 12 | E27: Cooktop a gás externo + abrigo P13 + kit instalação | G27: vb | H27: 1 | I27: =COUNTIFS(Cotações!$E$2:$E$2,$A27) | J27: =IF(I27=0,"—",_xlfn.MINIFS(Cotações!$J$2:$J$2,Cotações!$E$2:$E$2,$A27)) | K27: =IF(I27=0,"—",IFERROR(INDEX(Cotações!$H$2:$H$2,MATCH(1,INDEX((Cotações!$E$2:$E$2=$A27)*(Cotações!$J$2:$J$2=J27),0),0)),"")) | L27: =IF(I27=0,"—",IFERROR(J27*H27,"")) | M27: redundância — gás só na varanda
A28: IT025 | B28: Geral / Estrutura | C28: material | D28: 12 | E28: Bancada ilha: porcelanato sinterizado 12 mm + rebaixo italiano | G28: m² | H28: 5 | I28: =COUNTIFS(Cotações!$E$2:$E$2,$A28) | J28: =IF(I28=0,"—",_xlfn.MINIFS(Cotações!$J$2:$J$2,Cotações!$E$2:$E$2,$A28)) | K28: =IF(I28=0,"—",IFERROR(INDEX(Cotações!$H$2:$H$2,MATCH(1,INDEX((Cotações!$E$2:$E$2=$A28)*(Cotações!$J$2:$J$2=J28),0),0)),"")) | L28: =IF(I28=0,"—",IFERROR(J28*H28,"")) | M28: quartzo/resina NÃO compatível c/ Invisacook
A29: IT026 | B29: Geral / Estrutura | C29: material | D29: 12 | E29: Invisacook 4 zonas + acessórios (mantas, indicadores) | G29: un | H29: 1 | I29: =COUNTIFS(Cotações!$E$2:$E$2,$A29) | J29: =IF(I29=0,"—",_xlfn.MINIFS(Cotações!$J$2:$J$2,Cotações!$E$2:$E$2,$A29)) | K29: =IF(I29=0,"—",IFERROR(INDEX(Cotações!$H$2:$H$2,MATCH(1,INDEX((Cotações!$E$2:$E$2=$A29)*(Cotações!$J$2:$J$2=J29),0),0)),"")) | L29: =IF(I29=0,"—",IFERROR(J29*H29,"")) | M29: circuito 40 A na aba Elétrica
A30: IT027 | B30: Geral / Estrutura | C30: material | D30: 7 | E30: Janelão vertical fachada noroeste (vidro laminado) + película espelhada | F30: parede da escada · 3,20 × 4,70 m · peitoril 1,00 · caixilho estruturado | G30: m² | H30: 15 | I30: =COUNTIFS(Cotações!$E$2:$E$2,$A30) | J30: =IF(I30=0,"—",_xlfn.MINIFS(Cotações!$J$2:$J$2,Cotações!$E$2:$E$2,$A30)) | K30: =IF(I30=0,"—",IFERROR(INDEX(Cotações!$H$2:$H$2,MATCH(1,INDEX((Cotações!$E$2:$E$2=$A30)*(Cotações!$J$2:$J$2=J30),0),0)),"")) | L30: =IF(I30=0,"—",IFERROR(J30*H30,"")) | M30: CORRIGIDO: largura alinhada à planta F-02 (era 2,2 m no catálogo e 2,4 m na elevação — a planta sempre mostrou 3,20 m, cobrindo todo o lance da escada) · película espelhada só no trecho do piso superior; térreo com vidro transparente
A31: IT028 | B31: Hidráulica | C31: material | D31: 8 | E31: Tubo PEX 20 mm (água quente) | F31: PEX-A c/ barreira anti-O₂ | G31: m | H31: 75 | I31: =COUNTIFS(Cotações!$E$2:$E$2,$A31) | J31: =IF(I31=0,"—",_xlfn.MINIFS(Cotações!$J$2:$J$2,Cotações!$E$2:$E$2,$A31)) | K31: =IF(I31=0,"—",IFERROR(INDEX(Cotações!$H$2:$H$2,MATCH(1,INDEX((Cotações!$E$2:$E$2=$A31)*(Cotações!$J$2:$J$2=J31),0),0)),"")) | L31: =IF(I31=0,"—",IFERROR(J31*H31,"")) | M31: ramais quentes + anel de recirculação
A32: IT029 | B32: Hidráulica | C32: material | D32: 8 | E32: Isolamento térmico p/ PEX 20 mm | F32: polietileno exp. 10 mm parede | G32: m | H32: 75 | I32: =COUNTIFS(Cotações!$E$2:$E$2,$A32) | J32: =IF(I32=0,"—",_xlfn.MINIFS(Cotações!$J$2:$J$2,Cotações!$E$2:$E$2,$A32)) | K32: =IF(I32=0,"—",IFERROR(INDEX(Cotações!$H$2:$H$2,MATCH(1,INDEX((Cotações!$E$2:$E$2=$A32)*(Cotações!$J$2:$J$2=J32),0),0)),"")) | L32: =IF(I32=0,"—",IFERROR(J32*H32,"")) | M32: obrigatório em 100% da linha quente
A33: IT030 | B33: Hidráulica | C33: material | D33: 8 | E33: Tubo PEX 16/20 mm (água fria) | F33: PEX-A | G33: m | H33: 100 | I33: =COUNTIFS(Cotações!$E$2:$E$2,$A33) | J33: =IF(I33=0,"—",_xlfn.MINIFS(Cotações!$J$2:$J$2,Cotações!$E$2:$E$2,$A33)) | K33: =IF(I33=0,"—",IFERROR(INDEX(Cotações!$H$2:$H$2,MATCH(1,INDEX((Cotações!$E$2:$E$2=$A33)*(Cotações!$J$2:$J$2=J33),0),0)),"")) | L33: =IF(I33=0,"—",IFERROR(J33*H33,"")) | M33: ramais frios ponto a ponto (manifold)
A34: IT031 | B34: Hidráulica | C34: material | D34: 8 | E34: Tubo PPR PN25 32 mm | F34: barrilete caixa→pressurizador→manifolds/boiler | G34: m | H34: 18 | I34: =COUNTIFS(Cotações!$E$2:$E$2,$A34) | J34: =IF(I34=0,"—",_xlfn.MINIFS(Cotações!$J$2:$J$2,Cotações!$E$2:$E$2,$A34)) | K34: =IF(I34=0,"—",IFERROR(INDEX(Cotações!$H$2:$H$2,MATCH(1,INDEX((Cotações!$E$2:$E$2=$A34)*(Cotações!$J$2:$J$2=J34),0),0)),"")) | L34: =IF(I34=0,"—",IFERROR(J34*H34,""))
A35: IT032 | B35: Hidráulica | C35: material | D35: 8 | E35: Tubo PPR PN25 28 mm | F35: circuito bomba de calor ↔ boiler | G35: m | H35: 8 | I35: =COUNTIFS(Cotações!$E$2:$E$2,$A35) | J35: =IF(I35=0,"—",_xlfn.MINIFS(Cotações!$J$2:$J$2,Cotações!$E$2:$E$2,$A35)) | K35: =IF(I35=0,"—",IFERROR(INDEX(Cotações!$H$2:$H$2,MATCH(1,INDEX((Cotações!$E$2:$E$2=$A35)*(Cotações!$J$2:$J$2=J35),0),0)),"")) | L35: =IF(I35=0,"—",IFERROR(J35*H35,"")) | M35: isolar também
A36: IT033 | B36: Hidráulica | C36: material | D36: 8 | E36: Isolamento p/ PPR 28/32 mm | F36: polietileno exp. | G36: m | H36: 26 | I36: =COUNTIFS(Cotações!$E$2:$E$2,$A36) | J36: =IF(I36=0,"—",_xlfn.MINIFS(Cotações!$J$2:$J$2,Cotações!$E$2:$E$2,$A36)) | K36: =IF(I36=0,"—",IFERROR(INDEX(Cotações!$H$2:$H$2,MATCH(1,INDEX((Cotações!$E$2:$E$2=$A36)*(Cotações!$J$2:$J$2=J36),0),0)),"")) | L36: =IF(I36=0,"—",IFERROR(J36*H36,""))
A37: IT034 | B37: Hidráulica | C37: material | D37: 8 | E37: Tubo PVC soldável 25 mm | F37: alimentação da caixa + torneiras jardim/garagem | G37: m | H37: 20 | I37: =COUNTIFS(Cotações!$E$2:$E$2,$A37) | J37: =IF(I37=0,"—",_xlfn.MINIFS(Cotações!$J$2:$J$2,Cotações!$E$2:$E$2,$A37)) | K37: =IF(I37=0,"—",IFERROR(INDEX(Cotações!$H$2:$H$2,MATCH(1,INDEX((Cotações!$E$2:$E$2=$A37)*(Cotações!$J$2:$J$2=J37),0),0)),"")) | L37: =IF(I37=0,"—",IFERROR(J37*H37,""))
A38: IT035 | B38: Hidráulica | C38: material | D38: 8 | E38: Tubo PVC esgoto 100 mm | F38: prumadas de vasos + ventilação | G38: m | H38: 22 | I38: =COUNTIFS(Cotações!$E$2:$E$2,$A38) | J38: =IF(I38=0,"—",_xlfn.MINIFS(Cotações!$J$2:$J$2,Cotações!$E$2:$E$2,$A38)) | K38: =IF(I38=0,"—",IFERROR(INDEX(Cotações!$H$2:$H$2,MATCH(1,INDEX((Cotações!$E$2:$E$2=$A38)*(Cotações!$J$2:$J$2=J38),0),0)),"")) | L38: =IF(I38=0,"—",IFERROR(J38*H38,"")) | M38: 2 prumadas + coletor
A39: IT036 | B39: Hidráulica | C39: material | D39: 8 | E39: Tubo PVC esgoto 50 mm | F39: chuveiros, ralos, tanque, máquina | G39: m | H39: 25 | I39: =COUNTIFS(Cotações!$E$2:$E$2,$A39) | J39: =IF(I39=0,"—",_xlfn.MINIFS(Cotações!$J$2:$J$2,Cotações!$E$2:$E$2,$A39)) | K39: =IF(I39=0,"—",IFERROR(INDEX(Cotações!$H$2:$H$2,MATCH(1,INDEX((Cotações!$E$2:$E$2=$A39)*(Cotações!$J$2:$J$2=J39),0),0)),"")) | L39: =IF(I39=0,"—",IFERROR(J39*H39,""))
A40: IT037 | B40: Hidráulica | C40: material | D40: 8 | E40: Tubo PVC esgoto 40 mm | F40: lavatórios, pias, dreno boiler/copa | G40: m | H40: 15 | I40: =COUNTIFS(Cotações!$E$2:$E$2,$A40) | J40: =IF(I40=0,"—",_xlfn.MINIFS(Cotações!$J$2:$J$2,Cotações!$E$2:$E$2,$A40)) | K40: =IF(I40=0,"—",IFERROR(INDEX(Cotações!$H$2:$H$2,MATCH(1,INDEX((Cotações!$E$2:$E$2=$A40)*(Cotações!$J$2:$J$2=J40),0),0)),"")) | L40: =IF(I40=0,"—",IFERROR(J40*H40,""))
...

Sheet Cotações
A1: ID | B1: Data | C1: Tipo | D1: Categoria | E1: Item ID | F1: Item | G1: Etapa | H1: Fornecedor / empreiteiro | I1: Qtde | J1: Preço unit. | K1: Total | L1: Melhor? | M1: Observação
A3: Nenhuma cotação lançada ainda — use o formulário do site.

Sheet Comparativo
A1: COTADO × ESTIMADO POR ETAPA
A2: # | B2: Etapa | C2: Estim. baixa | D2: Estim. alta | E2: Real / cotado | F2: Δ vs. alta | G2: Situação
A3: 1 | B3: Projetos, sondagem e aprovações | C3: =Etapas!C3 | D3: =Etapas!D3 | E3: =IF(Etapas!I3>0,Etapas!I3,Etapas!L3) | F3: =IF(E3=0,"",D3-E3) | G3: =IF(E3=0,"sem cotação",IF(E3>D3,"ACIMA da faixa",IF(E3<C3,"abaixo da faixa","dentro da faixa")))
A4: 2 | B4: Fundação (radier 103 m²) + muro de divisa 210 m² | C4: =Etapas!C4 | D4: =Etapas!D4 | E4: =IF(Etapas!I4>0,Etapas!I4,Etapas!L4) | F4: =IF(E4=0,"",D4-E4) | G4: =IF(E4=0,"sem cotação",IF(E4>D4,"ACIMA da faixa",IF(E4<C4,"abaixo da faixa","dentro da faixa")))
A5: 3 | B5: Estrutura metálica | C5: =Etapas!C5 | D5: =Etapas!D5 | E5: =IF(Etapas!I5>0,Etapas!I5,Etapas!L5) | F5: =IF(E5=0,"",D5-E5) | G5: =IF(E5=0,"sem cotação",IF(E5>D5,"ACIMA da faixa",IF(E5<C5,"abaixo da faixa","dentro da faixa")))
A6: 4 | B6: Paredes: Monolev (estrutural) + divisórias Lightwall | C6: =Etapas!C6 | D6: =Etapas!D6 | E6: =IF(Etapas!I6>0,Etapas!I6,Etapas!L6) | F6: =IF(E6=0,"",D6-E6) | G6: =IF(E6=0,"sem cotação",IF(E6>D6,"ACIMA da faixa",IF(E6<C6,"abaixo da faixa","dentro da faixa")))
A7: 5 | B7: Lajes de PISO (superior + sacada + técnica) | C7: =Etapas!C7 | D7: =Etapas!D7 | E7: =IF(Etapas!I7>0,Etapas!I7,Etapas!L7) | F7: =IF(E7=0,"",D7-E7) | G7: =IF(E7=0,"sem cotação",IF(E7>D7,"ACIMA da faixa",IF(E7<C7,"abaixo da faixa","dentro da faixa")))
A8: 6 | B8: Cobertura + lanternim | C8: =Etapas!C8 | D8: =Etapas!D8 | E8: =IF(Etapas!I8>0,Etapas!I8,Etapas!L8) | F8: =IF(E8=0,"",D8-E8) | G8: =IF(E8=0,"sem cotação",IF(E8>D8,"ACIMA da faixa",IF(E8<C8,"abaixo da faixa","dentro da faixa")))
A9: 7 | B9: Esquadrias e vidros | C9: =Etapas!C9 | D9: =Etapas!D9 | E9: =IF(Etapas!I9>0,Etapas!I9,Etapas!L9) | F9: =IF(E9=0,"",D9-E9) | G9: =IF(E9=0,"sem cotação",IF(E9>D9,"ACIMA da faixa",IF(E9<C9,"abaixo da faixa","dentro da faixa")))
A10: 8 | B10: Hidráulica + água quente + prep. PV | C10: =Etapas!C10 | D10: =Etapas!D10 | E10: =IF(Etapas!I10>0,Etapas!I10,Etapas!L10) | F10: =IF(E10=0,"",D10-E10) | G10: =IF(E10=0,"sem cotação",IF(E10>D10,"ACIMA da faixa",IF(E10<C10,"abaixo da faixa","dentro da faixa")))
A11: 9 | B11: Elétrica + automação + rede | C11: =Etapas!C11 | D11: =Etapas!D11 | E11: =IF(Etapas!I11>0,Etapas!I11,Etapas!L11) | F11: =IF(E11=0,"",D11-E11) | G11: =IF(E11=0,"sem cotação",IF(E11>D11,"ACIMA da faixa",IF(E11<C11,"abaixo da faixa","dentro da faixa")))
A12: 10 | B12: Climatização | C12: =Etapas!C12 | D12: =Etapas!D12 | E12: =IF(Etapas!I12>0,Etapas!I12,Etapas!L12) | F12: =IF(E12=0,"",D12-E12) | G12: =IF(E12=0,"sem cotação",IF(E12>D12,"ACIMA da faixa",IF(E12<C12,"abaixo da faixa","dentro da faixa")))
A13: 11 | B13: Acabamentos resinados (sem porcelanato) | C13: =Etapas!C13 | D13: =Etapas!D13 | E13: =IF(Etapas!I13>0,Etapas!I13,Etapas!L13) | F13: =IF(E13=0,"",D13-E13) | G13: =IF(E13=0,"sem cotação",IF(E13>D13,"ACIMA da faixa",IF(E13<C13,"abaixo da faixa","dentro da faixa")))
A14: 12 | B14: Gourmet (Invisacook, bancada, churrasqueira) | C14: =Etapas!C14 | D14: =Etapas!D14 | E14: =IF(Etapas!I14>0,Etapas!I14,Etapas!L14) | F14: =IF(E14=0,"",D14-E14) | G14: =IF(E14=0,"sem cotação",IF(E14>D14,"ACIMA da faixa",IF(E14<C14,"abaixo da faixa","dentro da faixa")))
A15: 13 | B15: Canteiro, limpeza e imprevistos (~8%) | C15: =Etapas!C15 | D15: =Etapas!D15 | E15: =IF(Etapas!I15>0,Etapas!I15,Etapas!L15) | F15: =IF(E15=0,"",D15-E15) | G15: =IF(E15=0,"sem cotação",IF(E15>D15,"ACIMA da faixa",IF(E15<C15,"abaixo da faixa","dentro da faixa")))

Sheet Revisões
A1: HISTÓRICO DE REVISÕES DO PROJETO
A2: Data | B2: Alteração | C2: Impacto
A3: 13/07/2026 | B3: Versão inicial da planilha (13 etapas, 116 itens) | C3: Faixa R$ 498–764 mil
A4: 13/07/2026 | B4: Orientação corrigida: frente NOROESTE (não norte) | C4: Fachada frontal recebe sol da tarde — verificar conforto
A5: 13/07/2026 | B5: Janelão da escada c/ peitoril 1,00 m (2,2 × 4,70) | C5: Vidro 12 → 10,5 m²
A6: 13/07/2026 | B6: Vão da garagem em altura total (chão → laje), viga na testada | C6: Perfil da viga a validar (altura útil limitada)
A7: 15/07/2026 | B7: Esclarecido: lajes = SÓ pisos. Forro nivelado gesso+EPS incluído | C7: +47 m² de forro (antes ausente do orçamento)
A8: 15/07/2026 | B8: Forro de MADEIRA no mezanino/vão duplo acompanhando o telhado | C8: +45 m² · R$ 8–16 mil (item premium)
A9: 15/07/2026 | B9: Divisórias do superior migradas de Monolev p/ Lightwall 2P 90 | C9: Monolev 421 → 340 m² · Etapa 4: R$ 120–170k → R$ 110–156k
A10: 16/07/2026 | B10: Faixa NE: área de luz até a fachada, portinha recuada 0,80 | C10: Telha 105 → 98 m² · estrutura 100 → 95 m²
A11: 16/07/2026 | B11: Parede cega entre Luz 1 e Luz 2 · Luz 1 = jardim de inverno | C11: +14 m² parede verde · +12 m² janelão · impermeabilizar divisa
A12: 16/07/2026 | B12: Cobertura: pórticos de viga cheia → 3 TRELIÇAS @3,25 m | C12: Aço 1,4 t → ~1,0 t · degrau do lanternim triangulado
A13: 16/07/2026 | B13: Terças: 6 → 4 linhas e Ue 150 → Ue 100 | C13: −170 kg · σ 61 MPa (24% de fy), flecha L/483
... A34: 24/07/2026 | B34: Área técnica passa a ser ABERTA (sem porta, portão-gradil) c/ escada marinheiro na parede da Luz 2 | C34: Garante ar para a bomba de calor (11,5 m³ fechados seriam insuficientes; fabricantes exigem 15-20 m³ ou ventilação permanente) · exige equipamentos IP65

Sheet Fornecedores
A1: CONSOLIDADO POR FORNECEDOR / EMPREITEIRO
A2: Uma linha por fornecedor cotado no site — quem fornece o quê, em qual etapa e por quanto.
A3: Fornecedor / empreiteiro | B3: Tipo | C3: Nº de cotações | D3: Total cotado | E3: Etapas envolvidas | F3: Itens
A4: Nenhum fornecedor cotado ainda. Cada cotação lançada no site cria/alimenta uma linha aqui.
